[200~Digite o PID desejado: 2540
/home/fud3/Documents/git/3y3/./pid_grafico.py:28: SettingWithCopyWarning: 
A value is trying to be set on a copy of a slice from a DataFrame.
Try using .loc[row_indexer,col_indexer] = value instead

See the caveats in the documentation: https://pandas.pydata.org/pandas-docs/stable/user_guide/indexing.html#returning-a-view-versus-a-copy
  df_pid['Hora'] = pd.to_datetime(df_pid['Hora'])
Traceback (most recent call last):
  File /usr/lib/python3/dist-packages/pandas/core/indexes/base.py, line 3802, in get_loc
    return self._engine.get_loc(casted_key)
           ^^^^^^^^^^^^^^^^^^^^^^^^^^^^^^^^
  File pandas/_libs/index.pyx, line 138, in pandas._libs.index.IndexEngine.get_loc
  File pandas/_libs/index.pyx, line 165, in pandas._libs.index.IndexEngine.get_loc
  File pandas/_libs/hashtable_class_helper.pxi, line 5745, in pandas._libs.hashtable.PyObjectHashTable.get_item
  File pandas/_libs/hashtable_class_helper.pxi, line 5753, in pandas._libs.hashtable.PyObjectHashTable.get_item
KeyError: 'cpu'

The above exception was the direct cause of the following exception:

Traceback (most recent call last):
  File /home/fud3/Documents/git/3y3/./pid_grafico.py, line 57, in <module>
    gerar_grafico_pid(pid_desejado)
  File /home/fud3/Documents/git/3y3/./pid_grafico.py, line 37, in gerar_grafico_pid
    plt.plot(df_pid['Hora'], df_pid['cpu'], label='CPU (%)', color='blue')
                             ~~~~~~^^^^^^^
  File /usr/lib/python3/dist-packages/pandas/core/frame.py, line 3807, in __getitem__
    indexer = self.columns.get_loc(key)
              ^^^^^^^^^^^^^^^^^^^^^^^^^
  File /usr/lib/python3/dist-packages/pandas/core/indexes/base.py, line 3804, in get_loc
    raise KeyError(key) from err
KeyError: 'cpu'
~
